2023-10-14 01:29:20,458 INFO    Thread-212 (_run_job):58267 [wandb_setup.py:_flush():76] Current SDK version is 0.15.12
2023-10-14 01:29:20,458 INFO    Thread-212 (_run_job):58267 [wandb_setup.py:_flush():76] Configure stats pid to 58267
2023-10-14 01:29:20,458 INFO    Thread-212 (_run_job):58267 [wandb_setup.py:_flush():76] Loading settings from /home/ubuntulsa/.config/wandb/settings
2023-10-14 01:29:20,458 INFO    Thread-212 (_run_job):58267 [wandb_setup.py:_flush():76] Loading settings from /home/ubuntulsa/Sem5/SMAI/Assignment 3/wandb/settings
2023-10-14 01:29:20,458 INFO    Thread-212 (_run_job):58267 [wandb_setup.py:_flush():76] Loading settings from environment variables: {'project': 'mnist-cnn-hyperparam-tuning', 'entity': 'mourya', 'root_dir': '/home/ubuntulsa/Sem5/SMAI/Assignment 3', 'run_id': 'bg8fhymq', 'sweep_param_path': '/home/ubuntulsa/Sem5/SMAI/Assignment 3/wandb/sweep-052kumb5/config-bg8fhymq.yaml', 'sweep_id': '052kumb5'}
2023-10-14 01:29:20,458 INFO    Thread-212 (_run_job):58267 [wandb_setup.py:_flush():76] Applying setup settings: {'_disable_service': False}
2023-10-14 01:29:20,458 INFO    Thread-212 (_run_job):58267 [wandb_setup.py:_flush():76] Inferring run settings from compute environment: {'program': '<python with no main file>'}
2023-10-14 01:29:20,458 INFO    Thread-212 (_run_job):58267 [wandb_init.py:_log_setup():528] Logging user logs to /home/ubuntulsa/Sem5/SMAI/Assignment 3/wandb/run-20231014_012920-bg8fhymq/logs/debug.log
2023-10-14 01:29:20,458 INFO    Thread-212 (_run_job):58267 [wandb_init.py:_log_setup():529] Logging internal logs to /home/ubuntulsa/Sem5/SMAI/Assignment 3/wandb/run-20231014_012920-bg8fhymq/logs/debug-internal.log
2023-10-14 01:29:20,459 INFO    Thread-212 (_run_job):58267 [wandb_init.py:_jupyter_setup():474] configuring jupyter hooks <wandb.sdk.wandb_init._WandbInit object at 0x7fa89467db70>
2023-10-14 01:29:20,459 INFO    Thread-212 (_run_job):58267 [wandb_init.py:init():568] calling init triggers
2023-10-14 01:29:20,459 INFO    Thread-212 (_run_job):58267 [wandb_init.py:init():575] wandb.init called with sweep_config: {'batch_size': 128, 'dropout_rate': 0.5, 'epochs': 5, 'kernel_size': 3, 'learning_rate': 0.0001, 'stride': 1}
config: {}
2023-10-14 01:29:20,459 INFO    Thread-212 (_run_job):58267 [wandb_init.py:init():618] starting backend
2023-10-14 01:29:20,459 INFO    Thread-212 (_run_job):58267 [wandb_init.py:init():622] setting up manager
2023-10-14 01:29:20,466 INFO    Thread-212 (_run_job):58267 [backend.py:_multiprocessing_setup():105] multiprocessing start_methods=fork,spawn,forkserver, using: spawn
2023-10-14 01:29:20,467 INFO    Thread-212 (_run_job):58267 [wandb_init.py:init():628] backend started and connected
2023-10-14 01:29:20,476 INFO    Thread-212 (_run_job):58267 [wandb_run.py:_config_callback():1324] config_cb None None {'batch_size': 128, 'dropout_rate': 0.5, 'epochs': 5, 'kernel_size': 3, 'learning_rate': 0.0001, 'stride': 1}
2023-10-14 01:29:20,477 INFO    Thread-212 (_run_job):58267 [wandb_run.py:_label_probe_notebook():1276] probe notebook
2023-10-14 01:29:20,477 INFO    Thread-212 (_run_job):58267 [wandb_run.py:_label_probe_notebook():1286] Unable to probe notebook: 'NoneType' object has no attribute 'get'
2023-10-14 01:29:20,477 INFO    Thread-212 (_run_job):58267 [wandb_init.py:init():720] updated telemetry
2023-10-14 01:29:20,477 INFO    Thread-212 (_run_job):58267 [wandb_init.py:init():753] communicating run to backend with 90.0 second timeout
2023-10-14 01:29:21,702 INFO    Thread-212 (_run_job):58267 [wandb_run.py:_on_init():2220] communicating current version
2023-10-14 01:29:21,901 INFO    Thread-212 (_run_job):58267 [wandb_run.py:_on_init():2229] got version response 
2023-10-14 01:29:21,901 INFO    Thread-212 (_run_job):58267 [wandb_init.py:init():804] starting run threads in backend
2023-10-14 01:29:21,934 INFO    Thread-212 (_run_job):58267 [wandb_run.py:_console_start():2199] atexit reg
2023-10-14 01:29:21,934 INFO    Thread-212 (_run_job):58267 [wandb_run.py:_redirect():2054] redirect: wrap_raw
2023-10-14 01:29:21,934 INFO    Thread-212 (_run_job):58267 [wandb_run.py:_redirect():2119] Wrapping output streams.
2023-10-14 01:29:21,935 INFO    Thread-212 (_run_job):58267 [wandb_run.py:_redirect():2144] Redirects installed.
2023-10-14 01:29:21,935 INFO    Thread-212 (_run_job):58267 [wandb_init.py:init():845] run started, returning control to user process
2023-10-14 01:30:54,090 INFO    Thread-91 (_heartbeat):58267 [retry.py:__call__():172] Retry attempt failed:
Traceback (most recent call last):
  File "/home/ubuntulsa/.local/lib/python3.10/site-packages/urllib3/connection.py", line 203, in _new_conn
    sock = connection.create_connection(
  File "/home/ubuntulsa/.local/lib/python3.10/site-packages/urllib3/util/connection.py", line 60, in create_connection
    for res in socket.getaddrinfo(host, port, family, socket.SOCK_STREAM):
  File "/usr/lib/python3.10/socket.py", line 955, in getaddrinfo
    for res in _socket.getaddrinfo(host, port, family, type, proto, flags):
socket.gaierror: [Errno -3] Temporary failure in name resolution

The above exception was the direct cause of the following exception:

Traceback (most recent call last):
  File "/home/ubuntulsa/.local/lib/python3.10/site-packages/urllib3/connectionpool.py", line 790, in urlopen
    response = self._make_request(
  File "/home/ubuntulsa/.local/lib/python3.10/site-packages/urllib3/connectionpool.py", line 491, in _make_request
    raise new_e
  File "/home/ubuntulsa/.local/lib/python3.10/site-packages/urllib3/connectionpool.py", line 467, in _make_request
    self._validate_conn(conn)
  File "/home/ubuntulsa/.local/lib/python3.10/site-packages/urllib3/connectionpool.py", line 1092, in _validate_conn
    conn.connect()
  File "/home/ubuntulsa/.local/lib/python3.10/site-packages/urllib3/connection.py", line 611, in connect
    self.sock = sock = self._new_conn()
  File "/home/ubuntulsa/.local/lib/python3.10/site-packages/urllib3/connection.py", line 210, in _new_conn
    raise NameResolutionError(self.host, self, e) from e
urllib3.exceptions.NameResolutionError: <urllib3.connection.HTTPSConnection object at 0x7fa88f931c30>: Failed to resolve 'api.wandb.ai' ([Errno -3] Temporary failure in name resolution)

The above exception was the direct cause of the following exception:

Traceback (most recent call last):
  File "/home/ubuntulsa/.local/lib/python3.10/site-packages/requests/adapters.py", line 486, in send
    resp = conn.urlopen(
  File "/home/ubuntulsa/.local/lib/python3.10/site-packages/urllib3/connectionpool.py", line 844, in urlopen
    retries = retries.increment(
  File "/home/ubuntulsa/.local/lib/python3.10/site-packages/urllib3/util/retry.py", line 515, in increment
    raise MaxRetryError(_pool, url, reason) from reason  # type: ignore[arg-type]
urllib3.exceptions.MaxRetryError: HTTPSConnectionPool(host='api.wandb.ai', port=443): Max retries exceeded with url: /graphql (Caused by NameResolutionError("<urllib3.connection.HTTPSConnection object at 0x7fa88f931c30>: Failed to resolve 'api.wandb.ai' ([Errno -3] Temporary failure in name resolution)"))

During handling of the above exception, another exception occurred:

Traceback (most recent call last):
  File "/home/ubuntulsa/.local/lib/python3.10/site-packages/wandb/sdk/lib/retry.py", line 131, in __call__
    result = self._call_fn(*args, **kwargs)
  File "/home/ubuntulsa/.local/lib/python3.10/site-packages/wandb/sdk/internal/internal_api.py", line 366, in execute
    return self.client.execute(*args, **kwargs)  # type: ignore
  File "/home/ubuntulsa/.local/lib/python3.10/site-packages/wandb/vendor/gql-0.2.0/wandb_gql/client.py", line 52, in execute
    result = self._get_result(document, *args, **kwargs)
  File "/home/ubuntulsa/.local/lib/python3.10/site-packages/wandb/vendor/gql-0.2.0/wandb_gql/client.py", line 60, in _get_result
    return self.transport.execute(document, *args, **kwargs)
  File "/home/ubuntulsa/.local/lib/python3.10/site-packages/wandb/sdk/lib/gql_request.py", line 58, in execute
    request = self.session.post(self.url, **post_args)
  File "/home/ubuntulsa/.local/lib/python3.10/site-packages/requests/sessions.py", line 637, in post
    return self.request("POST", url, data=data, json=json, **kwargs)
  File "/home/ubuntulsa/.local/lib/python3.10/site-packages/requests/sessions.py", line 589, in request
    resp = self.send(prep, **send_kwargs)
  File "/home/ubuntulsa/.local/lib/python3.10/site-packages/requests/sessions.py", line 703, in send
    r = adapter.send(request, **kwargs)
  File "/home/ubuntulsa/.local/lib/python3.10/site-packages/requests/adapters.py", line 519, in send
    raise ConnectionError(e, request=request)
requests.exceptions.ConnectionError: HTTPSConnectionPool(host='api.wandb.ai', port=443): Max retries exceeded with url: /graphql (Caused by NameResolutionError("<urllib3.connection.HTTPSConnection object at 0x7fa88f931c30>: Failed to resolve 'api.wandb.ai' ([Errno -3] Temporary failure in name resolution)"))
2023-10-14 01:30:59,764 INFO    Thread-212 (_run_job):58267 [wandb_run.py:_finish():1934] finishing run mourya/mnist-cnn-hyperparam-tuning/bg8fhymq
2023-10-14 01:30:59,764 INFO    Thread-212 (_run_job):58267 [jupyter.py:save_history():445] not saving jupyter history
2023-10-14 01:30:59,764 INFO    Thread-212 (_run_job):58267 [jupyter.py:save_ipynb():373] not saving jupyter notebook
2023-10-14 01:30:59,764 INFO    Thread-212 (_run_job):58267 [wandb_init.py:_jupyter_teardown():456] cleaning up jupyter logic
2023-10-14 01:30:59,764 INFO    Thread-212 (_run_job):58267 [wandb_run.py:_atexit_cleanup():2168] got exitcode: 0
2023-10-14 01:30:59,764 INFO    Thread-212 (_run_job):58267 [wandb_run.py:_restore():2151] restore
2023-10-14 01:30:59,764 INFO    Thread-212 (_run_job):58267 [wandb_run.py:_restore():2157] restore done
