2023-10-12 13:33:12,951 INFO    StreamThr :387186 [internal.py:wandb_internal():86] W&B internal server running at pid: 387186, started at: 2023-10-12 13:33:12.951191
2023-10-12 13:33:12,953 DEBUG   HandlerThread:387186 [handler.py:handle_request():144] handle_request: status
2023-10-12 13:33:12,964 INFO    WriterThread:387186 [datastore.py:open_for_write():85] open: /home/ubuntulsa/Sem5/SMAI/Assignment 3/wandb/run-20231012_133312-8wshvwi4/run-8wshvwi4.wandb
2023-10-12 13:33:12,964 DEBUG   SenderThread:387186 [sender.py:send():380] send: header
2023-10-12 13:33:12,967 DEBUG   SenderThread:387186 [sender.py:send():380] send: run
2023-10-12 13:33:16,220 INFO    SenderThread:387186 [retry.py:__call__():172] Retry attempt failed:
Traceback (most recent call last):
  File "/home/ubuntulsa/.local/lib/python3.10/site-packages/urllib3/connection.py", line 203, in _new_conn
    sock = connection.create_connection(
  File "/home/ubuntulsa/.local/lib/python3.10/site-packages/urllib3/util/connection.py", line 60, in create_connection
    for res in socket.getaddrinfo(host, port, family, socket.SOCK_STREAM):
  File "/usr/local/lib/python3.10/socket.py", line 955, in getaddrinfo
    for res in _socket.getaddrinfo(host, port, family, type, proto, flags):
socket.gaierror: [Errno -2] Name or service not known

The above exception was the direct cause of the following exception:

Traceback (most recent call last):
  File "/home/ubuntulsa/.local/lib/python3.10/site-packages/urllib3/connectionpool.py", line 790, in urlopen
    response = self._make_request(
  File "/home/ubuntulsa/.local/lib/python3.10/site-packages/urllib3/connectionpool.py", line 491, in _make_request
    raise new_e
  File "/home/ubuntulsa/.local/lib/python3.10/site-packages/urllib3/connectionpool.py", line 467, in _make_request
    self._validate_conn(conn)
  File "/home/ubuntulsa/.local/lib/python3.10/site-packages/urllib3/connectionpool.py", line 1092, in _validate_conn
    conn.connect()
  File "/home/ubuntulsa/.local/lib/python3.10/site-packages/urllib3/connection.py", line 611, in connect
    self.sock = sock = self._new_conn()
  File "/home/ubuntulsa/.local/lib/python3.10/site-packages/urllib3/connection.py", line 210, in _new_conn
    raise NameResolutionError(self.host, self, e) from e
urllib3.exceptions.NameResolutionError: <urllib3.connection.HTTPSConnection object at 0x7f0e8768f1f0>: Failed to resolve 'api.wandb.ai' ([Errno -2] Name or service not known)

The above exception was the direct cause of the following exception:

Traceback (most recent call last):
  File "/home/ubuntulsa/.local/lib/python3.10/site-packages/requests/adapters.py", line 486, in send
    resp = conn.urlopen(
  File "/home/ubuntulsa/.local/lib/python3.10/site-packages/urllib3/connectionpool.py", line 844, in urlopen
    retries = retries.increment(
  File "/home/ubuntulsa/.local/lib/python3.10/site-packages/urllib3/util/retry.py", line 515, in increment
    raise MaxRetryError(_pool, url, reason) from reason  # type: ignore[arg-type]
urllib3.exceptions.MaxRetryError: HTTPSConnectionPool(host='api.wandb.ai', port=443): Max retries exceeded with url: /graphql (Caused by NameResolutionError("<urllib3.connection.HTTPSConnection object at 0x7f0e8768f1f0>: Failed to resolve 'api.wandb.ai' ([Errno -2] Name or service not known)"))

During handling of the above exception, another exception occurred:

Traceback (most recent call last):
  File "/home/ubuntulsa/.local/lib/python3.10/site-packages/wandb/sdk/lib/retry.py", line 131, in __call__
    result = self._call_fn(*args, **kwargs)
  File "/home/ubuntulsa/.local/lib/python3.10/site-packages/wandb/sdk/internal/internal_api.py", line 366, in execute
    return self.client.execute(*args, **kwargs)  # type: ignore
  File "/home/ubuntulsa/.local/lib/python3.10/site-packages/wandb/vendor/gql-0.2.0/wandb_gql/client.py", line 52, in execute
    result = self._get_result(document, *args, **kwargs)
  File "/home/ubuntulsa/.local/lib/python3.10/site-packages/wandb/vendor/gql-0.2.0/wandb_gql/client.py", line 60, in _get_result
    return self.transport.execute(document, *args, **kwargs)
  File "/home/ubuntulsa/.local/lib/python3.10/site-packages/wandb/sdk/lib/gql_request.py", line 58, in execute
    request = self.session.post(self.url, **post_args)
  File "/home/ubuntulsa/.local/lib/python3.10/site-packages/requests/sessions.py", line 637, in post
    return self.request("POST", url, data=data, json=json, **kwargs)
  File "/home/ubuntulsa/.local/lib/python3.10/site-packages/requests/sessions.py", line 589, in request
    resp = self.send(prep, **send_kwargs)
  File "/home/ubuntulsa/.local/lib/python3.10/site-packages/requests/sessions.py", line 703, in send
    r = adapter.send(request, **kwargs)
  File "/home/ubuntulsa/.local/lib/python3.10/site-packages/requests/adapters.py", line 519, in send
    raise ConnectionError(e, request=request)
requests.exceptions.ConnectionError: HTTPSConnectionPool(host='api.wandb.ai', port=443): Max retries exceeded with url: /graphql (Caused by NameResolutionError("<urllib3.connection.HTTPSConnection object at 0x7f0e8768f1f0>: Failed to resolve 'api.wandb.ai' ([Errno -2] Name or service not known)"))
2023-10-12 13:33:17,974 DEBUG   HandlerThread:387186 [handler.py:handle_request():144] handle_request: keepalive
2023-10-12 13:33:22,978 DEBUG   HandlerThread:387186 [handler.py:handle_request():144] handle_request: keepalive
2023-10-12 13:33:27,983 DEBUG   HandlerThread:387186 [handler.py:handle_request():144] handle_request: keepalive
2023-10-12 13:33:32,988 DEBUG   HandlerThread:387186 [handler.py:handle_request():144] handle_request: keepalive
2023-10-12 13:33:37,992 DEBUG   HandlerThread:387186 [handler.py:handle_request():144] handle_request: keepalive
2023-10-12 13:33:42,997 DEBUG   HandlerThread:387186 [handler.py:handle_request():144] handle_request: keepalive
2023-10-12 13:33:48,000 DEBUG   HandlerThread:387186 [handler.py:handle_request():144] handle_request: keepalive
2023-10-12 13:33:53,005 DEBUG   HandlerThread:387186 [handler.py:handle_request():144] handle_request: keepalive
2023-10-12 13:33:58,009 DEBUG   HandlerThread:387186 [handler.py:handle_request():144] handle_request: keepalive
2023-10-12 13:34:03,013 DEBUG   HandlerThread:387186 [handler.py:handle_request():144] handle_request: keepalive
2023-10-12 13:34:08,017 DEBUG   HandlerThread:387186 [handler.py:handle_request():144] handle_request: keepalive
2023-10-12 13:34:13,022 DEBUG   HandlerThread:387186 [handler.py:handle_request():144] handle_request: keepalive
2023-10-12 13:34:18,026 DEBUG   HandlerThread:387186 [handler.py:handle_request():144] handle_request: keepalive
2023-10-12 13:34:23,031 DEBUG   HandlerThread:387186 [handler.py:handle_request():144] handle_request: keepalive
2023-10-12 13:34:28,036 DEBUG   HandlerThread:387186 [handler.py:handle_request():144] handle_request: keepalive
2023-10-12 13:34:33,040 DEBUG   HandlerThread:387186 [handler.py:handle_request():144] handle_request: keepalive
2023-10-12 13:34:38,045 DEBUG   HandlerThread:387186 [handler.py:handle_request():144] handle_request: keepalive
2023-10-12 13:34:43,048 DEBUG   HandlerThread:387186 [handler.py:handle_request():144] handle_request: cancel
2023-10-12 13:34:43,048 DEBUG   HandlerThread:387186 [handler.py:handle_request():144] handle_request: cancel
2023-10-12 13:34:43,048 DEBUG   SenderThread:387186 [sender.py:send():389] Record cancelled: run
2023-10-12 13:34:43,049 DEBUG   HandlerThread:387186 [handler.py:handle_request():144] handle_request: status_report
2023-10-12 13:34:48,049 DEBUG   HandlerThread:387186 [handler.py:handle_request():144] handle_request: status_report
2023-10-12 13:34:53,050 DEBUG   HandlerThread:387186 [handler.py:handle_request():144] handle_request: status_report
2023-10-12 13:34:55,263 DEBUG   HandlerThread:387186 [handler.py:handle_request():144] handle_request: shutdown
2023-10-12 13:34:55,263 INFO    HandlerThread:387186 [handler.py:finish():844] shutting down handler
2023-10-12 13:34:56,051 INFO    SenderThread:387186 [sender.py:finish():1534] shutting down sender
2023-10-12 13:34:56,051 INFO    WriterThread:387186 [datastore.py:close():294] close: /home/ubuntulsa/Sem5/SMAI/Assignment 3/wandb/run-20231012_133312-8wshvwi4/run-8wshvwi4.wandb
